[2024-06-22T07:37:51.980+0000] {local_task_job_runner.py:120} INFO - ::group::Pre task execution logs
[2024-06-22T07:37:51.991+0000] {taskinstance.py:2076} INFO - Dependencies all met for dep_context=non-requeueable deps ti=<TaskInstance: first_dag_v2.second_task manual__2024-06-22T07:37:50.061876+00:00 [queued]>
[2024-06-22T07:37:51.995+0000] {taskinstance.py:2076} INFO - Dependencies all met for dep_context=requeueable deps ti=<TaskInstance: first_dag_v2.second_task manual__2024-06-22T07:37:50.061876+00:00 [queued]>
[2024-06-22T07:37:51.995+0000] {taskinstance.py:2306} INFO - Starting attempt 1 of 6
[2024-06-22T07:37:52.002+0000] {taskinstance.py:2330} INFO - Executing <Task(BashOperator): second_task> on 2024-06-22 07:37:50.061876+00:00
[2024-06-22T07:37:52.004+0000] {warnings.py:112} WARNING - /home/***/.local/lib/python3.12/site-packages/***/task/task_runner/standard_task_runner.py:61: DeprecationWarning: This process (pid=1937) is multi-threaded, use of fork() may lead to deadlocks in the child.
  pid = os.fork()

[2024-06-22T07:37:52.005+0000] {standard_task_runner.py:63} INFO - Started process 1938 to run task
[2024-06-22T07:37:52.005+0000] {standard_task_runner.py:90} INFO - Running: ['***', 'tasks', 'run', 'first_dag_v2', 'second_task', 'manual__2024-06-22T07:37:50.061876+00:00', '--job-id', '10', '--raw', '--subdir', 'DAGS_FOLDER/first_dag.py', '--cfg-path', '/tmp/tmpzij97xny']
[2024-06-22T07:37:52.006+0000] {standard_task_runner.py:91} INFO - Job 10: Subtask second_task
[2024-06-22T07:37:52.027+0000] {task_command.py:426} INFO - Running <TaskInstance: first_dag_v2.second_task manual__2024-06-22T07:37:50.061876+00:00 [running]> on host 65f8df8d6172
[2024-06-22T07:37:52.063+0000] {taskinstance.py:2648} INFO - Exporting env vars: AIRFLOW_CTX_DAG_OWNER='gnosia93' AIRFLOW_CTX_DAG_ID='first_dag_v2' AIRFLOW_CTX_TASK_ID='second_task' AIRFLOW_CTX_EXECUTION_DATE='2024-06-22T07:37:50.061876+00:00' AIRFLOW_CTX_TRY_NUMBER='1' AIRFLOW_CTX_DAG_RUN_ID='manual__2024-06-22T07:37:50.061876+00:00'
[2024-06-22T07:37:52.063+0000] {taskinstance.py:430} INFO - ::endgroup::
[2024-06-22T07:37:52.069+0000] {subprocess.py:63} INFO - Tmp dir root location: /tmp
[2024-06-22T07:37:52.070+0000] {subprocess.py:75} INFO - Running command: ['/usr/bin/bash', '-c', "echo I'm second task, .. gnosia93"]
[2024-06-22T07:37:52.074+0000] {subprocess.py:86} INFO - Output:
[2024-06-22T07:37:52.075+0000] {subprocess.py:93} INFO - /usr/bin/bash: -c: line 1: unexpected EOF while looking for matching `''
[2024-06-22T07:37:52.075+0000] {subprocess.py:97} INFO - Command exited with return code 2
[2024-06-22T07:37:52.076+0000] {taskinstance.py:441} INFO - ::group::Post task execution logs
[2024-06-22T07:37:52.081+0000] {taskinstance.py:2905} ERROR - Task failed with exception
Traceback (most recent call last):
  File "/home/airflow/.local/lib/python3.12/site-packages/airflow/models/taskinstance.py", line 465, in _execute_task
    result = _execute_callable(context=context, **execute_callable_kwargs)
             ^^^^^^^^^^^^^^^^^^^^^^^^^^^^^^^^^^^^^^^^^^^^^^^^^^^^^^^^^^^^^
  File "/home/airflow/.local/lib/python3.12/site-packages/airflow/models/taskinstance.py", line 432, in _execute_callable
    return execute_callable(context=context, **execute_callable_kwargs)
           ^^^^^^^^^^^^^^^^^^^^^^^^^^^^^^^^^^^^^^^^^^^^^^^^^^^^^^^^^^^^
  File "/home/airflow/.local/lib/python3.12/site-packages/airflow/models/baseoperator.py", line 401, in wrapper
    return func(self, *args, **kwargs)
           ^^^^^^^^^^^^^^^^^^^^^^^^^^^
  File "/home/airflow/.local/lib/python3.12/site-packages/airflow/operators/bash.py", line 243, in execute
    raise AirflowException(
airflow.exceptions.AirflowException: Bash command failed. The command returned a non-zero exit code 2.
[2024-06-22T07:37:52.083+0000] {taskinstance.py:1206} INFO - Marking task as UP_FOR_RETRY. dag_id=first_dag_v2, task_id=second_task, run_id=manual__2024-06-22T07:37:50.061876+00:00, execution_date=20240622T073750, start_date=20240622T073751, end_date=20240622T073752
[2024-06-22T07:37:52.090+0000] {standard_task_runner.py:110} ERROR - Failed to execute job 10 for task second_task (Bash command failed. The command returned a non-zero exit code 2.; 1938)
[2024-06-22T07:37:52.106+0000] {local_task_job_runner.py:240} INFO - Task exited with return code 1
[2024-06-22T07:37:52.118+0000] {taskinstance.py:3503} INFO - 0 downstream tasks scheduled from follow-on schedule check
[2024-06-22T07:37:52.118+0000] {local_task_job_runner.py:222} INFO - ::endgroup::
